Workbook

Sheet 00_Portada
A1: MAESTRO PK-16 | Mantenimiento y dimensionamiento
A2: Libro consolidado. Datos originales separados de las capas limpias, de análisis y de control.
A4: Propósito
A5: Consultar el parque, criticidad, MEB ECO, montaje, paros, cuellos de botella y dimensionamiento FTE desde una única estructura actualizable.
A8: Fuente 1 | B8: MAESTRO_FABRICA_FINAL.xlsx
A9: Fuente 2 | B9: DIMENSIONAMIENTO_MANTENIMIENTO_DATOS_FINAL.xlsx
A10: Criterio de clasificación | B10: Los 2.043 activos están clasificados en A/B/C/D.
A11: Plantilla nominal | B11: 80 personas
A12: Necesidad calculada | B12: 114,21 a 123,70 FTE
A13: Uso recomendado | B13: Actualizar primero las tablas limpias o los archivos fuente; revisar después Comprobaciones y Dashboard.
A16: Código de color
A17: Importado / vinculado
A18: Fórmula / calculado
A19: Entrada editable
A20: Advertencia / revisión
A21: Error / incoherencia

Sheet 10_Resumen_Ejecutivo
A1: Resumen ejecutivo
A2: Visión consolidada para dirección. Los valores de dimensionamiento se calculan desde la hoja 30_Dimensionamiento.
A4: Parque total | D4: Plantilla actual | G4: Necesidad mínima
A5: ='30_Dimensionamiento'!B9 -> 2043 | D5: ='30_Dimensionamiento'!B22 -> 80 | G5: ='30_Dimensionamiento'!B34 -> 114.20672
A8: Necesidad máxima | D8: Gap mínimo | G8: Gap máximo
A9: ='30_Dimensionamiento'!B35 -> 123.69601 | D9: ='30_Dimensionamiento'!B36 -> 34.206723 | G9: ='30_Dimensionamiento'!B37 -> 43.696009
A13: Distribución por criticidad | E13: MEB ECO crítico confirmado
A14: Criticidad | B14: Activos | C14: FTE base | E14: Producto | F14: Total crítico
A15: A | B15: ='30_Dimensionamiento'!B5 -> 418 | C15: ='30_Dimensionamiento'!B14 -> 34.833333 | E15: KMM | F15: 15
A16: B | B16: ='30_Dimensionamiento'!B6 -> 275 | C16: ='30_Dimensionamiento'!B15 -> 13.75 | E16: EBOX | F16: 14
A17: C | B17: ='30_Dimensionamiento'!B7 -> 1200 | C17: ='30_Dimensionamiento'!B16 -> 34.285714 | E17: Conjunto Diferencial | F17: 14
A18: D | B18: ='30_Dimensionamiento'!B8 -> 150 | C18: ='30_Dimensionamiento'!B17 -> 2.5 | E18: Manguetas | F18: 17
E19: Aluminio GGH/MGH | F19: 15
A21: Conclusión
A22: El modelo sitúa la necesidad entre 114 y 124 FTE frente a una plantilla nominal de 80 personas. El déficit calculado queda entre 34 y 44 FTE. La base estructural se obtiene de los 2.043 activos clasificados por criticidad A/B/C/D.

Sheet 11_Dashboard
A1: Dashboard de mantenimiento
A2: Indicadores de criticidad, dimensionamiento, MEB ECO y eventos de paro.
A4: Parque total | D4: Base criticidad | G4: Gap mínimo | J4: Gap máximo
A5: ='30_Dimensionamiento'!B9 -> 2043 | D5: ='30_Dimensionamiento'!B18 -> 85.369048 | G5: ='30_Dimensionamiento'!B36 -> 34.206723 | J5: ='30_Dimensionamiento'!B37 -> 43.696009
A30: Criticidad | B30: Activos | D30: Escenario | E30: FTE | G30: Producto | H30: Críticos
A31: A | B31: ='31_Analisis'!G5 -> 418 | D31: Plantilla | E31: ='30_Dimensionamiento'!B22 -> 80 | G31: KMM | H31: ='31_Analisis'!B13 -> 15
A32: B | B32: ='31_Analisis'!G6 -> 275 | D32: Necesidad mín. | E32: ='30_Dimensionamiento'!B34 -> 114.20672 | G32: EBOX | H32: ='31_Analisis'!B14 -> 14
A33: C | B33: ='31_Analisis'!G7 -> 1200 | D33: Necesidad máx. | E33: ='30_Dimensionamiento'!B35 -> 123.69601 | G33: Conjunto Diferencial | H33: ='31_Analisis'!B15 -> 14
A34: D | B34: ='31_Analisis'!G8 -> 150 | G34: Manguetas | H34: ='31_Analisis'!B16 -> 17
G35: Aluminio GGH/MGH | H35: ='31_Analisis'!B17 -> 15

Sheet ORG_M_00_Resumen_Ejecutivo
A1: MAESTRO COMPLETO DE FÁBRICA | Mantenimiento
A2: Integra contexto fábrica, paros, cuellos, montaje MQ-200/MQ-281, MEB ECO y dimensionamiento. No inventa inventarios faltantes.
A4: Indicador | B4: Valor | C4: Lectura
A5: Alcance detallado en histórico de paros | B5: 1247 | C5: Máquinas/objetos con paros agrupados
A6: Montaje en fichero actualizado | B6: 264 | C6: Incluye MQ-200/KRAUSE, MQ-281/SCHMID y nuevos productos
A7: Cuellos de botella | B7: 129 | C7: Todos A1 por definición
A8: MEB ECO crítico confirmado | B8: 75 | C8: Programa global: 5 productos
A9: MEB ECO montaje crítico | B9: 56 | C9: KMM 15 + EBOX 14 + Diferencial 10 + Manguetas 17
A10: MEB ECO mecanizado crítico | B10: 19 | C10: Diferencial 4 Reishauer + Aluminio GGH/MGH 15
A11: Plantilla actual | B11: 80 | C11: Personas de mantenimiento aprox. facilitadas por usuario
A12: Referencia base ajustada | B12: 100 | C12: Mantenedores equivalentes por carga ponderada
A13: Referencia base equilibrada | B13: 114 | C13: Mantenedores equivalentes por carga ponderada
A14: Gap base | B14: 20 - 34 | C14: Diferencia vs plantilla actual
A15: Referencia con PM/TPM no absorbido | B15: 110 - 124 | C15: Sirve si PM/TPM no está ya integrado en plantilla
A16: Gap con PM/TPM | B16: 30 - 44 | C16: Diferencia vs plantilla actual
A19: Producto MEB ECO | B19: Montaje crítico | C19: Mecanizado crítico | D19: Total crítico
A20: KMM | B20: 15 | C20: 0 | D20: 15
A21: EBOX | B21: 14 | C21: 0 | D21: 14
A22: Conjunto Diferencial | B22: 10 | C22: 4 | D22: 14
A23: Manguetas | B23: 17 | C23: 0 | D23: 17
A24: Aluminio GGH/MGH | B24: 0 | C24: 15 | D24: 15
A25: TOTAL | B25: 56 | C25: 19 | D25: 75

Sheet ORG_M_01_Maestro_Fabrica
A1: Maestro fábrica consolidado
A2: Vista única por bloque: global fábrica, MEB ECO oficial, montaje, cuellos y paros. El campo Veracidad indica el nivel de confianza.
A3: Bloque | B3: Producto / Familia / Activo | C3: Proceso / Ubicación | D3: Cantidad | E3: Descripción / Inventario | F3: Criticidad | G3: Estado | H3: Fuente | I3: Veracidad | J3: Comentario
A4: Contexto fábrica | B4: Mecanizado | C4: Global | D4: 430 | E4: Máquinas de mecanizado | H4: Dato global de presentación | I4: Dato global - no inventario individual | J4: Contexto / dimensionamiento
A5: Contexto fábrica | B5: Robots | C5: Global | D5: 92 | E5: Robots KUKA/FANUC/ABB/Universal | H5: Dato global de presentación | I5: Dato global - no inventario individual | J5: Contexto / dimensionamiento
A6: Contexto fábrica | B6: Montaje | C6: Global | D6: 264 | E6: Filas de montaje en fichero actualizado. Incluye MQ-200, MQ-281 y MEB ECO con reservas/standby | H6: Fichero montaje actualizado | I6: Dato global - no inventario individual | J6: Contexto / dimensionamiento
A7: Contexto fábrica | B7: Tratamientos y fundición | C7: Global | D7: 58 | E7: Instalaciones de tratamientos térmicos y fundición | H7: Dato global de presentación | I7: Dato global - no inventario individual | J7: Contexto / dimensionamiento
A8: Contexto fábrica | B8: Calidad | C8: Global | D8: 290 | E8: Puestos de calidad, medición y control | H8: Dato global de presentación | I8: Dato global - no inventario individual | J8: Contexto / dimensionamiento
A9: Contexto fábrica | B9: Lavadoras | C9: Global | D9: 74 | E9: Lavadoras automáticas | H9: Dato global de presentación | I9: Dato global - no inventario individual | J9: Contexto / dimensionamiento
A10: Contexto fábrica | B10: Transporte instalaciones | C10: Global | D10: 355 | E10: Instalaciones de transporte | H10: Dato global de presentación | I10: Dato global - no inventario individual | J10: Contexto / dimensionamiento
A11: Contexto fábrica | B11: Medios de transporte | C11: Global | D11: 386 | E11: Carros, apiladores, potros | H11: Dato global de presentación | I11: Dato global - no inventario individual | J11: Contexto / dimensionamiento
A12: Contexto fábrica | B12: Auxiliares producción | C12: Global | D12: 94 | E12: Ingrávidos, atemperadores, aspiradores y auxiliares | H12: Dato global de presentación | I12: Dato global - no inventario individual | J12: Contexto / dimensionamiento
A13: Contexto fábrica | B13: Preventivos | C13: Global | D13: 9000 | E13: Más de 9.000 planes PM | H13: Dato global de presentación | I13: Dato global - no inventario individual | J13: Contexto / dimensionamiento
A14: Contexto fábrica | B14: Puntos PM | C14: Global | D14: 50000 | E14: Más de 50.000 puntos PM | H14: Dato global de presentación | I14: Dato global - no inventario individual | J14: Contexto / dimensionamiento
A15: Contexto fábrica | B15: Avisos intervención | C15: Global | D15: 10000 | E15: Más de 10.000 avisos/año | H15: Dato global de presentación | I15: Dato global - no inventario individual | J15: Contexto / dimensionamiento
... A17: Contexto fábrica | B17: Horas máquina parada | C17: Global | D17: 10000 | E17: 10.000 h de máquina parada declaradas | H17: Dato global de presentación | I17: Dato global - no inventario individual | J17: Contexto / dimensionamiento
A18: MEB ECO oficial | B18: KMM | C18: Montaje | D18: 15 | E18: Estaciones de montaje críticas | F18: A1 | G18: Total confirmado; faltan inventarios exactos en ficheros | H18: Dato de negocio facilitado por usuario | I18: Total verificado por negocio | J18: Criticidad
A19: MEB ECO oficial | B19: EBOX | C19: Montaje | D19: 14 | E19: Estaciones de montaje críticas | F19: A1 | G19: Total confirmado; faltan inventarios exactos en ficheros | H19: Dato de negocio facilitado por usuario | I19: Total verificado por negocio | J19: Criticidad
A20: MEB ECO oficial | B20: Conjunto Diferencial | C20: Montaje | D20: 10 | E20: Estaciones de montaje críticas | F20: A1 | G20: Total confirmado; faltan inventarios exactos en ficheros | H20: Dato de negocio facilitado por usuario | I20: Total verificado por negocio | J20: Criticidad
A21: MEB ECO oficial | B21: Conjunto Diferencial | C21: Mecanizado | D21: 4 | E21: Rectificadoras Reishauer críticas | F21: A1 | G21: Total confirmado; faltan inventarios exactos en ficheros | H21: Dato de negocio facilitado por usuario | I21: Total verificado por negocio | J21: Criticidad
A22: MEB ECO oficial | B22: Manguetas | C22: Montaje | D22: 17 | E22: Estaciones de montaje críticas | F22: A1 | G22: Total confirmado; faltan inventarios exactos en ficheros | H22: Dato de negocio facilitado por usuario | I22: Total verificado por negocio | J22: Criticidad
A23: MEB ECO oficial | B23: Aluminio GGH/MGH | C23: Mecanizado | D23: 15 | E23: Máquinas críticas: centros de mecanizado y equipos principales | F23: A1 | G23: Total confirmado; faltan inventarios exactos en ficheros | H23: Dato de negocio facilitado por usuario | I23: Total verificado por negocio | J23: Criticidad
A24: Montaje detalle | B24: MQ-200 | C24: Montaje | D24: 1 | E24: 7016420001/215H | F24: A1 - Montaje | G24: Activo candidato | H24: Regla: KRAUSE/7016420001/7016420002 | I24: Inventario fuente montaje | J24: PRENSADO RODAMIENTOS Y CASQUILLOS CAR. DE EMBRAGUE REALIZADO POR THYSSENKRUPP
A25: Montaje detalle | B25: Manguetas | C25: Montaje | D25: 1 | E25: 7016424001/10H | F25: A1 - MEB ECO montaje candidato | G25: Activo candidato | H25: Regla: THYSSEN/Manguetas/7016424001 | I25: Inventario fuente montaje | J25: PUESTO DE CARGA DE MATERIAL
A26: Montaje detalle | B26: Manguetas | C26: Montaje | D26: 1 | E26: 7016424001/20A | F26: A1 - MEB ECO montaje candidato | G26: Activo candidato | H26: Regla: THYSSEN/Manguetas/7016424001 | I26: Inventario fuente montaje | J26: ATORNILLADO DE CHAPA Y SENSOR ABS
A27: Montaje detalle | B27: Manguetas | C27: Montaje | D27: 1 | E27: 7016424001/25 S/R | F27: C/Pendiente - revisar | G27: Standby/Reparación/Reserva | H27: Regla: THYSSEN/Manguetas/7016424001 | I27: Inventario fuente montaje | J27: STANDBY / REPARACIÓN
A28: Montaje detalle | B28: Manguetas | C28: Montaje | D28: 1 | E28: 7016424001/30A | F28: A1 - MEB ECO montaje candidato | G28: Activo candidato | H28: Regla: THYSSEN/Manguetas/7016424001 | I28: Inventario fuente montaje | J28: CARGA Y ATORNILLADO DE RODAMIENTO
A29: Montaje detalle | B29: Manguetas | C29: Montaje | D29: 1 | E29: 7016424001/35 S/R | F29: C/Pendiente - revisar | G29: Standby/Reparación/Reserva | H29: Regla: THYSSEN/Manguetas/7016424001 | I29: Inventario fuente montaje | J29: STANDBY / REPARACIÓN
... A169: Montaje detalle | B169: MQ-200 | C169: Montaje | D169: 1 | E169: 7016420001/300A | F169: A1 - Montaje | G169: Activo candidato | H169: Regla: KRAUSE/7016420001/7016420002 | I169: Inventario fuente montaje | J169: ESTACION DE VOLTEO MQ CON ROBOT KUKA 8536339069 (LOZANO)
A170: Montaje detalle | B170: Sin clasificar | C170: Montaje | D170: 1 | F170: A1 - Montaje | G170: Activo candidato | H170: Pendiente clasificar | I170: Inventario fuente montaje | J170: NUEVA ESTACION 20H QUE SUSTITUYE A LA ANTERIOR
A171: Montaje detalle | B171: MQ-200 | C171: Montaje | D171: 1 | E171: 7016420002/130A | F171: A1 - Montaje | G171: Activo candidato | H171: Regla: KRAUSE/7016420001/7016420002 | I171: Inventario fuente montaje | J171: ESTACION CONTROL CARRUSEL CON ROBOT ABB TRASPASE
A172: Montaje detalle | B172: MQ-200 | C172: Montaje | D172: 1 | E172: 7016420001/412H | F172: A1 - Montaje | G172: Activo candidato | H172: Regla: KRAUSE/7016420001/7016420002 | I172: Inventario fuente montaje | J172: NUEVA PSEUDOCABECERA LINEA 1 (Cueto)
A173: Montaje detalle | B173: MQ-200 | C173: Montaje | D173: 1 | E173: 7016420001/275A | F173: A1 - Montaje | G173: Activo candidato | H173: Regla: KRAUSE/7016420001/7016420002 | I173: Inventario fuente montaje | J173: ESTACIÓN DE VOLTEADO Y CIERRE DE CAMBIO. ROBOT ABB
A174: Montaje detalle | B174: Conjunto Diferencial | C174: Montaje | D174: 1 | E174: 7016426001 | F174: A1 - MEB ECO montaje candidato | G174: Activo candidato | H174: Regla: ORBITA/7016426001/Diferencial MEB ECO | I174: Inventario fuente montaje | J174: ARMARIO ELECTRICO PRENSA
A175: Montaje detalle | B175: Conjunto Diferencial | C175: Montaje | D175: 1 | E175: 7016426001 | F175: A1 - MEB ECO montaje candidato | G175: Activo candidato | H175: Regla: ORBITA/7016426001/Diferencial MEB ECO | I175: Inventario fuente montaje | J175: ARMARIO ELECTRICO RODADORA
A176: Montaje detalle | B176: Conjunto Diferencial | C176: Montaje | D176: 1 | E176: 7016426001 | F176: A1 - MEB ECO montaje candidato | G176: Activo candidato | H176: Regla: ORBITA/7016426001/Diferencial MEB ECO | I176: Inventario fuente montaje | J176: ARMARIO ELECTRICO TRASNPORTE Y ESTACIONES MANUALES
A177: Montaje detalle | B177: Conjunto Diferencial | C177: Montaje | D177: 1 | E177: 7016426001 | F177: A1 - MEB ECO montaje candidato | G177: Activo candidato | H177: Regla: ORBITA/7016426001/Diferencial MEB ECO | I177: Inventario fuente montaje | J177: ARMARIO DE DISTRIBUCIÓN KV
A178: Montaje detalle | B178: EBOX | C178: Montaje | D178: 1 | E178: 7016308001/05 | F178: A1 - MEB ECO montaje candidato | G178: Activo candidato | H178: Regla: DSA/EBOX/7016308001 | I178: Inventario fuente montaje | J178: Armario de transporte y estaciones manueales
A179: Montaje detalle | B179: EBOX | C179: Montaje | D179: 1 | E179: 7016308001/10 | F179: A1 - MEB ECO montaje candidato | G179: Activo candidato | H179: Regla: DSA/EBOX/7016308001 | I179: Inventario fuente montaje | J179: Carga Material
A180: Montaje detalle | B180: EBOX | C180: Montaje | D180: 1 | E180: 7016308001/20 | F180: A1 - MEB ECO montaje candidato | G180: Activo candidato | H180: Regla: DSA/EBOX/7016308001 | I180: Inventario fuente montaje | J180: Carga Material y Pre Atornillado
...

Sheet ORG_M_02_MEB_ECO_Oficial
A1: MEB ECO oficial | E productos
A2: Esta hoja manda sobre cruces automáticos. Total crítico confirmado: 75 activos.
A3: Programa | B3: Producto | C3: Proceso | D3: Tipo activo crítico | E3: Total crítico confirmado | F3: Identificados en ficheros | G3: Pendientes inventario exacto | H3: Criticidad | I3: Estado trazabilidad | J3: Fuente
A4: MEB ECO | B4: KMM | C4: Montaje | D4: Estaciones de montaje críticas | E4: 15 | F4: 14 | G4: 1 | H4: A1 | I4: Total confirmado; faltan inventarios exactos en ficheros | J4: Dato de negocio facilitado por usuario
A5: MEB ECO | B5: EBOX | C5: Montaje | D5: Estaciones de montaje críticas | E5: 14 | F5: 13 | G5: 1 | H5: A1 | I5: Total confirmado; faltan inventarios exactos en ficheros | J5: Dato de negocio facilitado por usuario
A6: MEB ECO | B6: Conjunto Diferencial | C6: Montaje | D6: Estaciones de montaje críticas | E6: 10 | F6: 4 | G6: 6 | H6: A1 | I6: Total confirmado; faltan inventarios exactos en ficheros | J6: Dato de negocio facilitado por usuario
A7: MEB ECO | B7: Conjunto Diferencial | C7: Mecanizado | D7: Rectificadoras Reishauer críticas | E7: 4 | F7: 2 | G7: 2 | H7: A1 | I7: Total confirmado; faltan inventarios exactos en ficheros | J7: Dato de negocio facilitado por usuario
A8: MEB ECO | B8: Manguetas | C8: Montaje | D8: Estaciones de montaje críticas | E8: 17 | F8: 14 | G8: 3 | H8: A1 | I8: Total confirmado; faltan inventarios exactos en ficheros | J8: Dato de negocio facilitado por usuario
A9: MEB ECO | B9: Aluminio GGH/MGH | C9: Mecanizado | D9: Máquinas críticas: centros de mecanizado y equipos principales | E9: 15 | F9: 0 | G9: 15 | H9: A1 | I9: Total confirmado; faltan inventarios exactos en ficheros | J9: Dato de negocio facilitado por usuario

Sheet ORG_M_03_MEB_ECO_Detalle
A1: MEB ECO detalle trazable
A2: Registros disponibles del fichero. Los faltantes del control oficial no se inventan.
A3: Inventario / Activo | B3: Producto | C3: Proceso | D3: Fabricante | E3: Modelo | F3: Grupo / Ubicación | G3: Año | H3: Tecnología | I3: Estado | J3: Comentario / carga | K3: Fuente producto
A4: 7016424001/10H | B4: Manguetas | C4: Montaje | D4: THYSSENKRUPP | E4: LINEA MANGUETAS | G4: 2024 | I4: Activo candidato | J4: PUESTO DE CARGA DE MATERIAL | K4: Regla: THYSSEN/Manguetas/7016424001
A5: 7016424001/20A | B5: Manguetas | C5: Montaje | D5: THYSSENKRUPP | E5: LINEA MANGUETAS | G5: 2024 | I5: Activo candidato | J5: ATORNILLADO DE CHAPA Y SENSOR ABS | K5: Regla: THYSSEN/Manguetas/7016424001
A6: 7016424001/25 S/R | B6: Manguetas | C6: Montaje | D6: THYSSENKRUPP | E6: LINEA MANGUETAS | G6: 2024 | I6: Standby/Reparación/Reserva | J6: STANDBY / REPARACIÓN | K6: Regla: THYSSEN/Manguetas/7016424001
A7: 7016424001/30A | B7: Manguetas | C7: Montaje | D7: THYSSENKRUPP | E7: LINEA MANGUETAS | G7: 2024 | I7: Activo candidato | J7: CARGA Y ATORNILLADO DE RODAMIENTO | K7: Regla: THYSSEN/Manguetas/7016424001
A8: 7016424001/35 S/R | B8: Manguetas | C8: Montaje | D8: THYSSENKRUPP | E8: LINEA MANGUETAS | G8: 2024 | I8: Standby/Reparación/Reserva | J8: STANDBY / REPARACIÓN | K8: Regla: THYSSEN/Manguetas/7016424001
A9: 7016424001/40A | B9: Manguetas | C9: Montaje | D9: THYSSENKRUPP | E9: LINEA MANGUETAS | G9: 2024 | I9: Activo candidato | J9: CARGA Y ATORNILLADO DE DISCO DE FRENO | K9: Regla: THYSSEN/Manguetas/7016424001
A10: 7016424001/45 S/R | B10: Manguetas | C10: Montaje | D10: THYSSENKRUPP | E10: LINEA MANGUETAS | G10: 2024 | I10: Standby/Reparación/Reserva | J10: STANDBY / REPARACIÓN | K10: Regla: THYSSEN/Manguetas/7016424001
A11: 7016424001/50A | B11: Manguetas | C11: Montaje | D11: THYSSENKRUPP | E11: LINEA MANGUETAS | G11: 2024 | I11: Activo candidato | J11: TEST DE ALABEO, CONTROL DE GIRO, Y ABS | K11: Regla: THYSSEN/Manguetas/7016424001
A12: 7016424001/55 S/R | B12: Manguetas | C12: Montaje | D12: THYSSENKRUPP | E12: LINEA MANGUETAS | G12: 2024 | I12: Standby/Reparación/Reserva | J12: STANDBY / REPARACIÓN | K12: Regla: THYSSEN/Manguetas/7016424001
A13: 7016424001/60A | B13: Manguetas | C13: Montaje | D13: THYSSENKRUPP | E13: LINEA MANGUETAS | G13: 2024 | I13: Activo candidato | J13: VOLTEO MANGUETAS Y ATORNILLADO DE RÓTULA | K13: Regla: THYSSEN/Manguetas/7016424001
A14: 7016424001/65 S/R | B14: Manguetas | C14: Montaje | D14: THYSSENKRUPP | E14: LINEA MANGUETAS | G14: 2024 | I14: Standby/Reparación/Reserva | J14: STANDBY / REPARACIÓN | K14: Regla: THYSSEN/Manguetas/7016424001
A15: 7016424001/70A | B15: Manguetas | C15: Montaje | D15: THYSSENKRUPP | E15: LINEA MANGUETAS | G15: 2024 | I15: Activo candidato | J15: CARGA DE PINZAS DE FRENO | K15: Regla: THYSSEN/Manguetas/7016424001
... A24: 7016424001/130A | B24: Manguetas | C24: Montaje | D24: THYSSENKRUPP | E24: LINEA MANGUETAS | G24: 2024 | I24: Activo candidato | J24: LIMPIEZA DE PALET | K24: Regla: THYSSEN/Manguetas/7016424001
A25: 7016426001 | B25: Conjunto Diferencial | C25: Montaje | D25: ORBITA | E25: LINEA MONTAJE DIFERENCIAL MEB ECO | H25: CPU 1517-3 F PN | I25: Activo candidato | J25: ARMARIO ELECTRICO PRENSA | K25: Regla: ORBITA/7016426001/Diferencial MEB ECO
A26: 7016426001 | B26: Conjunto Diferencial | C26: Montaje | D26: ORBITA | E26: LINEA MONTAJE DIFERENCIAL MEB ECO | H26: CPU 1517-3 F PN | I26: Activo candidato | J26: ARMARIO ELECTRICO RODADORA | K26: Regla: ORBITA/7016426001/Diferencial MEB ECO
A27: 7016426001 | B27: Conjunto Diferencial | C27: Montaje | D27: ORBITA | E27: LINEA MONTAJE DIFERENCIAL MEB ECO | H27: CPU 1517-3 F PN | I27: Activo candidato | J27: ARMARIO ELECTRICO TRASNPORTE Y ESTACIONES MANUALES | K27: Regla: ORBITA/7016426001/Diferencial MEB ECO
A28: 7016426001 | B28: Conjunto Diferencial | C28: Montaje | D28: ORBITA | E28: LINEA MONTAJE DIFERENCIAL MEB ECO | I28: Activo candidato | J28: ARMARIO DE DISTRIBUCIÓN KV | K28: Regla: ORBITA/7016426001/Diferencial MEB ECO
A29: 7016308001/05 | B29: EBOX | C29: Montaje | D29: DSA | E29: LINEA EBOX | I29: Activo candidato | J29: Armario de transporte y estaciones manueales | K29: Regla: DSA/EBOX/7016308001
A30: 7016308001/10 | B30: EBOX | C30: Montaje | D30: DSA | E30: LINEA EBOX | I30: Activo candidato | J30: Carga Material | K30: Regla: DSA/EBOX/7016308001
A31: 7016308001/20 | B31: EBOX | C31: Montaje | D31: DSA | E31: LINEA EBOX | I31: Activo candidato | J31: Carga Material y Pre Atornillado | K31: Regla: DSA/EBOX/7016308001
A32: 7016308001/30 | B32: EBOX | C32: Montaje | D32: DSA | E32: LINEA EBOX | I32: Activo candidato | J32: Atornillado y Clipado | K32: Regla: DSA/EBOX/7016308001
A33: 7016308001/40 | B33: EBOX | C33: Montaje | D33: DSA | E33: LINEA EBOX | I33: Activo candidato | J33: Cerrado de -Box y +Box | K33: Regla: DSA/EBOX/7016308001
A34: 7016308001/50 | B34: EBOX | C34: Montaje | D34: DSA | E34: LINEA EBOX | I34: Activo candidato | J34: Atornillado Reles | K34: Regla: DSA/EBOX/7016308001
A35: 7016308001/60 | B35: EBOX | C35: Montaje | D35: DSA | E35: LINEA EBOX | I35: Activo candidato | J35: Volteo | K35: Regla: DSA/EBOX/7016308001
A36: 7016308001/65 | B36: EBOX | C36: Montaje | D36: DSA | E36: LINEA EBOX | I36: Standby/Reparación/Reserva | J36: Puesto de recuperacion | K36: Regla: DSA/EBOX/7016308001
A37: 7016308001/80 | B37: EBOX | C37: Montaje | D37: DSA | E37: LINEA EBOX | I37: Activo candidato | J37: Volteo | K37: Regla: DSA/EBOX/7016308001
A38: 7016308001/90 | B38: EBOX | C38: Montaje | D38: DSA | E38: LINEA EBOX | I38: Activo candidato | J38: Pegado Isofolie | K38: Regla: DSA/EBOX/7016308001
A39: 7016308001/100 | B39: EBOX | C39: Montaje | D39: DSA | E39: LINEA EBOX | I39: Activo candidato | J39: Pegado GaP PAD | K39: Regla: DSA/EBOX/7016308001
... A55: 7016427001/200 | B55: KMM | C55: Montaje | D55: IBERFLUID | E55: LINEA KMM | I55: Activo candidato | J55: Transporte y estaciones manuales | K55: Regla: IBERFLUID/KMM/7016427001
A56: RECTIFICADORA REISHAUER 6773939006 | B56: Conjunto Diferencial | C56: Mecanizado | D56: REISHAUER | F56: Gr.65904 MQ-281 Conjunto Diferencial | I56: Crítica A1 por criterio negocio | J56: 100.1 h; 74 avisos | K56: Histórico paros
A57: RECTIFICADORA REISHAUER 6773939007 | B57: Conjunto Diferencial | C57: Mecanizado | D57: REISHAUER | F57: Gr.65904 MQ-281 Conjunto Diferencial | I57: Crítica A1 por criterio negocio | J57: 50.8 h; 79 avisos | K57: Histórico paros

Sheet ORG_M_04_Montaje_Completo
A1: Montaje completo | MQ-200, MQ-281 y MEB ECO
A2: Todas las filas del fichero de montaje clasificadas. No todas equivalen a estación crítica activa.
A3: Inventario | B3: Inventario antiguo | C3: Programa | D3: Producto | E3: Proceso | F3: Fabricante | G3: Modelo | H3: Grupo | I3: Año | J3: Tecnología | K3: Estado | L3: Comentario | M3: Regla producto
A4: 7016420001/215H | B4: 7016420001/215H-90410/215H | C4: Convencional | D4: MQ-200 | E4: Montaje | F4: KRAUSE | G4: ------------------------- | H4: 63425 | I4: 2017 | J4: PLC | K4: Activo candidato | L4: PRENSADO RODAMIENTOS Y CASQUILLOS CAR. DE EMBRAGUE REALIZADO POR THYSSENKRUPP | M4: Regla: KRAUSE/7016420001/7016420002
A5: 7016424001/10H | B5: 7016424001/10H | C5: MEB ECO | D5: Manguetas | E5: Montaje | F5: THYSSENKRUPP | G5: LINEA MANGUETAS | I5: 2024 | K5: Activo candidato | L5: PUESTO DE CARGA DE MATERIAL | M5: Regla: THYSSEN/Manguetas/7016424001
A6: 7016424001/20A | B6: 7016424001/20A | C6: MEB ECO | D6: Manguetas | E6: Montaje | F6: THYSSENKRUPP | G6: LINEA MANGUETAS | I6: 2024 | K6: Activo candidato | L6: ATORNILLADO DE CHAPA Y SENSOR ABS | M6: Regla: THYSSEN/Manguetas/7016424001
A7: 7016424001/25 S/R | B7: 7016424001/25 S/R | C7: MEB ECO | D7: Manguetas | E7: Montaje | F7: THYSSENKRUPP | G7: LINEA MANGUETAS | I7: 2024 | K7: Standby/Reparación/Reserva | L7: STANDBY / REPARACIÓN | M7: Regla: THYSSEN/Manguetas/7016424001
A8: 7016424001/30A | B8: 7016424001/30A | C8: MEB ECO | D8: Manguetas | E8: Montaje | F8: THYSSENKRUPP | G8: LINEA MANGUETAS | I8: 2024 | K8: Activo candidato | L8: CARGA Y ATORNILLADO DE RODAMIENTO | M8: Regla: THYSSEN/Manguetas/7016424001
A9: 7016424001/35 S/R | B9: 7016424001/35 S/R | C9: MEB ECO | D9: Manguetas | E9: Montaje | F9: THYSSENKRUPP | G9: LINEA MANGUETAS | I9: 2024 | K9: Standby/Reparación/Reserva | L9: STANDBY / REPARACIÓN | M9: Regla: THYSSEN/Manguetas/7016424001
A10: 7016424001/40A | B10: 7016424001/40A | C10: MEB ECO | D10: Manguetas | E10: Montaje | F10: THYSSENKRUPP | G10: LINEA MANGUETAS | I10: 2024 | K10: Activo candidato | L10: CARGA Y ATORNILLADO DE DISCO DE FRENO | M10: Regla: THYSSEN/Manguetas/7016424001
A11: 7016424001/45 S/R | B11: 7016424001/45 S/R | C11: MEB ECO | D11: Manguetas | E11: Montaje | F11: THYSSENKRUPP | G11: LINEA MANGUETAS | I11: 2024 | K11: Standby/Reparación/Reserva | L11: STANDBY / REPARACIÓN | M11: Regla: THYSSEN/Manguetas/7016424001
A12: 7016424001/50A | B12: 7016424001/50A | C12: MEB ECO | D12: Manguetas | E12: Montaje | F12: THYSSENKRUPP | G12: LINEA MANGUETAS | I12: 2024 | K12: Activo candidato | L12: TEST DE ALABEO, CONTROL DE GIRO, Y ABS | M12: Regla: THYSSEN/Manguetas/7016424001
A13: 7016424001/55 S/R | B13: 7016424001/55 S/R | C13: MEB ECO | D13: Manguetas | E13: Montaje | F13: THYSSENKRUPP | G13: LINEA MANGUETAS | I13: 2024 | K13: Standby/Reparación/Reserva | L13: STANDBY / REPARACIÓN | M13: Regla: THYSSEN/Manguetas/7016424001
A14: 7016424001/60A | B14: 7016424001/60A | C14: MEB ECO | D14: Manguetas | E14: Montaje | F14: THYSSENKRUPP | G14: LINEA MANGUETAS | I14: 2024 | K14: Activo candidato | L14: VOLTEO MANGUETAS Y ATORNILLADO DE RÓTULA | M14: Regla: THYSSEN/Manguetas/7016424001
A15: 7016424001/65 S/R | B15: 7016424001/65 S/R | C15: MEB ECO | D15: Manguetas | E15: Montaje | F15: THYSSENKRUPP | G15: LINEA MANGUETAS | I15: 2024 | K15: Standby/Reparación/Reserva | L15: STANDBY / REPARACIÓN | M15: Regla: THYSSEN/Manguetas/7016424001
A16: 7016424001/70A | B16: 7016424001/70A | C16: MEB ECO | D16: Manguetas | E16: Montaje | F16: THYSSENKRUPP | G16: LINEA MANGUETAS | I16: 2024 | K16: Activo candidato | L16: CARGA DE PINZAS DE FRENO | M16: Regla: THYSSEN/Manguetas/7016424001
... A25: 7016424001/130A | B25: 7016424001/130A | C25: MEB ECO | D25: Manguetas | E25: Montaje | F25: THYSSENKRUPP | G25: LINEA MANGUETAS | I25: 2024 | K25: Activo candidato | L25: LIMPIEZA DE PALET | M25: Regla: THYSSEN/Manguetas/7016424001
A26: 7016420001/230H | B26: 7016420001/230H-90410/230H | C26: Convencional | D26: MQ-200 | E26: Montaje | F26: KRAUSE | G26: ------------------------- | H26: 63425 | I26: 1999 | J26: PLC | K26: Activo candidato | L26: MEDICION DE ARANDELA MQ1 | M26: Regla: KRAUSE/7016420001/7016420002
A27: 7016420001/240H | B27: 7016420001/240H-90410/240H | C27: Convencional | D27: MQ-200 | E27: Montaje | F27: KRAUSE | G27: ------------------------- | H27: 63425 | I27: 1999 | J27: PLC | K27: Activo candidato | L27: PRENSADO PISTA DIFERENCIAL MQ1 | M27: Regla: KRAUSE/7016420001/7016420002
A28: 7016420001/220A | B28: 7016420001/220A-90410/220A | C28: Convencional | D28: MQ-200 | E28: Montaje | F28: KRAUSE | G28: ------------------------- | H28: 63425 | I28: 1999 | J28: PLC | K28: Activo candidato | L28: MEDICION DE ARANDELA MQ1 | M28: Regla: KRAUSE/7016420001/7016420002
A29: 7016420001/150H | B29: 7016420001/150H-90410/150H | C29: Convencional | D29: MQ-200 | E29: Montaje | F29: KRAUSE | G29: ------------------------- | H29: 63425 | I29: 1999 | J29: PLC | K29: Activo candidato | L29: APLICACIÓN SEGER Y HORQUILLA 5ª MQ1 | M29: Regla: KRAUSE/7016420001/7016420002
A30: 7016420001/160A | B30: 7016420001/160A-90410/160A | C30: Convencional | D30: MQ-200 | E30: Montaje | F30: KRAUSE | G30: ------------------------- | H30: 63425 | I30: 1999 | J30: PLC | K30: Activo candidato | L30: CONTROL ANILLOS DE SEGURIDAD MQ1 | M30: Regla: KRAUSE/7016420001/7016420002
A31: 7016420001/20H | B31: 7016420001/20H-90410/20H | C31: Convencional | D31: MQ-200 | E31: Montaje | F31: KRAUSE | G31: ------------------------- | H31: 63425 | I31: 1999 | J31: PLC | K31: Activo candidato | L31: MONTAJE DIFERENCIAL MQ1 | M31: Regla: KRAUSE/7016420001/7016420002
A32: 7016420001/30H | B32: 7016420001/30H-90410/30H | C32: Convencional | D32: MQ-200 | E32: Montaje | F32: KRAUSE | G32: ------------------------- | H32: 63425 | I32: 1999 | J32: PLC | K32: Activo candidato | L32: PRENSADO RODAMIENTO CONICO MQ1 | M32: Regla: KRAUSE/7016420001/7016420002
A33: 7016420001/40H | B33: 7016420001/40H-90410/40H | C33: Convencional | D33: MQ-200 | E33: Montaje | F33: KRAUSE | G33: ------------------------- | H33: 63425 | I33: 1999 | J33: PLC | K33: Activo candidato | L33: MONTAJE EJE PRIMARIO MQ1 | M33: Regla: KRAUSE/7016420001/7016420002
A34: 7016420001/50H | B34: 7016420001/50H-90410/50H | C34: Convencional | D34: MQ-200 | E34: Montaje | F34: KRAUSE | G34: ------------------------- | H34: 63425 | I34: 1999 | J34: PLC | K34: Activo candidato | L34: MONTAJE EJE SECUNDARIO MQ1 | M34: Regla: KRAUSE/7016420001/7016420002
A35: 7016420001/60A | B35: 7016420001/60A-90410/60A | C35: Convencional | D35: MQ-200 | E35: Montaje | F35: KRAUSE | G35: ------------------------- | H35: 63425 | I35: 1999 | J35: PLC-CNC | K35: Activo candidato | L35: ALMACEN PRIM/SEC/DIFERENC. MQ1 | M35: Regla: KRAUSE/7016420001/7016420002
A36: 7016420001/70H | B36: 7016420001/70H-90410/70H | C36: Convencional | D36: MQ-200 | E36: Montaje | F36: KRAUSE | G36: ------------------------ | H36: 63425 | I36: 1999 | J36: PLC | K36: Activo candidato | L36: PREMONTAJE CAJA CAMBIO MQ1 | M36: Regla: KRAUSE/7016420001/7016420002
A37: 7016420001/90H | B37: 7016420001/90H-90410/90H | C37: Convencional | D37: MQ-200 | E37: Montaje | F37: KRAUSE | G37: ------------------------- | H37: 63425 | I37: 1999 | J37: PLC | K37: Activo candidato | L37: MONTAJE EJES MQ1 | M37: Regla: KRAUSE/7016420001/7016420002
A38: 7016420001/100H | B38: 7016420001/100H-90410/100H | C38: Convencional | D38: MQ-200 | E38: Montaje | F38: KRAUSE | G38: ------------------------- | H38: 63425 | I38: 1999 | J38: PLC | K38: Activo candidato | L38: PRENSADO EJES MQ1 | M38: Regla: KRAUSE/7016420001/7016420002
A39: 7016420001/120H | B39: 7016420001/120H-90410/120H | C39: Convencional | D39: MQ-200 | E39: Montaje | F39: KRAUSE | H39: 63425 | I39: 1999 | J39: PLC | K39: Activo candidato | L39: ESTACION DE CARGA MQ1 | M39: Regla: KRAUSE/7016420001/7016420002
A40: 7016420001/200H | B40: 7016420001/200H-90410/200H | C40: Convencional | D40: MQ-200 | E40: Montaje | F40: KRAUSE | G40: ------------------------- | H40: 63425 | I40: 1999 | J40: PLC-PC | K40: Activo candidato | L40: PREMONTAJE CARCASA EMBRAGUE MQ1 | M40: Regla: KRAUSE/7016420001/7016420002
A41: 7016420001/250A | B41: 7016420001/250A-90410/250A | C41: Convencional | D41: MQ-200 | E41: Montaje | F41: KRAUSE | G41: ------------------------- | H41: 63425 | I41: 1999 | J41: PLC-CNC | K41: Activo candidato | L41: APLICACION JUNTA LIQUIDA MQ1 | M41: Regla: KRAUSE/7016420001/7016420002
A42: 7016420001/600H | B42: 7016420001/600H-90410/600H | C42: Convencional | D42: MQ-200 | E42: Montaje | F42: KRAUSE | G42: ------------------------- | H42: 63425 | I42: 1999 | J42: PLC | K42: Activo candidato | L42: DESMONTAJE CAMBIO | M42: Regla: KRAUSE/7016420001/7016420002
A43: 7016420001/300A | B43: 7016420001/300A-90410/300A | C43: Convencional | D43: MQ-200 | E43: Montaje | F43: KRAUSE | G43: ------------------------- | H43: 63425 | I43: 1999 | J43: PLC | K43: Activo candidato | L43: ESTACION DE VOLTEO MQ1 (SUSITUIDA POR UNA NUEVA JULIO 2016) | M43: Regla: KRAUSE/7016420001/7016420002
A44: 7016420001/140H | B44: 7016420001/140H-90410/140H | C44: Convencional | D44: MQ-200 | E44: Montaje | F44: KRAUSE | G44: ------------------------- | H44: 63425 | I44: 1999 | J44: PLC | K44: Activo candidato | L44: MONTAJE 5ª VELOCIDAD MQ1 | M44: Regla: KRAUSE/7016420001/7016420002
A45: 7016420001/35H | B45: 7016420001/35H-90410/35H | C45: Convencional | D45: MQ-200 | E45: Montaje | F45: KRAUSE | G45: ------------------------- | H45: 63425 | I45: 1999 | J45: PLC | K45: Activo candidato | L45: PREMONTAJE ANILLO 1/2 | M45: Regla: KRAUSE/7016420001/7016420002
A46: 7016420001/350A | B46: 7016420001/350A-90410/350A | C46: Convencional | D46: MQ-200 | E46: Montaje | F46: KRAUSE | G46: ------------------------- | H46: 63425 | I46: 1999 | J46: PLC | K46: Activo candidato | L46: ATORNILLADO TAPA 5ª Y VOLTEO MQ1(MODIFICADA 5/2006) | M46: Regla: KRAUSE/7016420001/7016420002
A47: 7016420001/380H | B47: 7016420001/380H-90410/380H | C47: Convencional | D47: MQ-200 | E47: Montaje | F47: KRAUSE | G47: ------------------------- | H47: 63425 | I47: 1999 | J47: PLC | K47: Activo candidato | L47: PRENSADO RETEN RADIAL MQ1 | M47: Regla: KRAUSE/7016420001/7016420002
A48: 7016420001/390H | B48: 7016420001/390H-90410/390H | C48: Convencional | D48: MQ-200 | E48: Montaje | F48: KRAUSE | G48: ------------------------- | H48: 63425 | I48: 1999 | J48: PLC | K48: Activo candidato | L48: MONTAJE DE SEMIPALIERES MQ1 | M48: Regla: KRAUSE/7016420001/7016420002
...

Sheet ORG_M_05_Paros_Historico
A1: Histórico de paros completo
A2: Totalizador de paros sin reasignaciones de producto no verificadas.
A3: Máquina | B3: Ubicación principal | C3: Horas paro | D3: Minutos paro | E3: Registros | F3: Registros P=X | G3: % P=X | H3: Media min/reg | I3: Máx min paro | J3: Categorías principales | K3: Comentarios frecuentes | L3: Años
A4: SOLDADORA PROBEAM (EB) 7016420005/3 | B4: Gr.65904 Soldadura en Duro | C4: 404.55 | D4: 24273 | E4: 399 | F4: 175 | G4: 0.43859649 | H4: 60.834586 | I4: 2100 | J4: Otros (167); Neumatica / aire (93); Robot / carga / manipulacion (48) | K4: perdida de vacio (17); problemas de vacio (9); fallo vacio (8) | L4: 2022, 2023, 2024, 2025, 2026
A5: GRANALLADORA WHEELABRATOR 6868217001 | B5: Gr. 65904 Rectificado.Ka | C5: 355.76667 | D5: 21346 | E5: 196 | F5: 92 | G5: 0.46938776 | H5: 108.90816 | I5: 8700 | J5: Granalla (129); Electrico / PLC / PC / comunicacion (17); Robot / carga / manipulacion (16) | K5: mesa no gira (5); mesa clavada (4); fuga de granalla (4) | L5: 2022, 2023, 2024, 2025, 2026
A6: TORNO TAKISAWA 6782941001 | B6: Grupo torneado | C6: 302.78333 | D6: 18167 | E6: 147 | F6: 95 | G6: 0.6462585 | H6: 123.58503 | I6: 4320 | J6: Otros (31); Robot / carga / manipulacion (28); Mecanica / desgaste / rotura (24) | K6: anomalia pales almacen de carga (2); tpm 41001 (2); al cortar tension torre se descuelga (1) | L6: 2022, 2023, 2024, 2025, 2026
A7: DENTADORA LIEBHERR 90405 | B7: Gr. 66209 Ejes Primario (Blanco) | C7: 297.73333 | D7: 17864 | E7: 119 | F7: 73 | G7: 0.61344538 | H7: 150.11765 | I7: 1500 | J7: Mecanica / desgaste / rotura (61); Robot / carga / manipulacion (29); Calidad / medicion / proceso (16) | K7: mal mecanizado. (6); mal mecanizado (5); no referencia eje v (3) | L7: 2022, 2023, 2024, 2025, 2026
A8: GRANALLADORA ALJU 6868221001 | B8: Gr. 31303 Rebabado Cajas -Carcasas | C8: 284.76667 | D8: 17086 | E8: 57 | F8: 11 | G8: 0.19298246 | H8: 299.75439 | I8: 10500 | J8: Granalla (38); Robot / carga / manipulacion (6); Neumatica / aire (3) | K8: averia alju automatica (3); tambor no gira (2); fallo cilindro (2) | L8: 2022, 2023, 2024, 2025, 2026
A9: RECTIFICADORA REISHAUER 6773936001 | B9: Gr. 65904 Rectificado GaPlus | C9: 269 | D9: 16140 | E9: 179 | F9: 99 | G9: 0.55307263 | H9: 90.167598 | I9: 848 | J9: Otros (72); Robot / carga / manipulacion (22); Calidad / medicion / proceso (20) | K9: averia contrasoporte (3); mal mecanizado (3); mala calidad (2) | L9: 2022, 2023, 2024, 2025, 2026
A10: LAMINADORA PROFIROLL 6776922003 | B10: 66302 MQ-281 Engranajes Blanco | C10: 267.13333 | D10: 16028 | E10: 125 | F10: 76 | G10: 0.608 | H10: 128.224 | I10: 1400 | J10: Robot / carga / manipulacion (51); Mecanica / desgaste / rotura (29); Otros (28) | K10: avería giro cargador (3); cargador tira las piezas (3); colisión cargador (2) | L10: 2022, 2023, 2024, 2025, 2026
A11: SOLDADORA P.T.R. 90007 | B11: 66302 P.T.R | C11: 259.7 | D11: 15582 | E11: 103 | F11: 50 | G11: 0.48543689 | H11: 151.28155 | I11: 2400 | J11: Otros (57); Electrico / PLC / PC / comunicacion (12); Robot / carga / manipulacion (8) | K11: no arranca pc (3); falla luz puesto control (1); plato 2 anulado no descarga una pieza. (1) | L11: 2022, 2023, 2024, 2025, 2026
A12: RECTIFICADORA REISHAUER 6773936002 | B12: Gr. 65904 Rectificado GaPlus | C12: 259.21667 | D12: 15553 | E12: 41 | F12: 23 | G12: 0.56097561 | H12: 379.34146 | I12: 7304 | J12: Otros (10); Hidraulica / aceite (8); Seguridad / puertas / protecciones (6) | K12: anomalia apertura puerta operador (1); eje my vigilancia posicion (1); tpm-r 213806 fuga de aceite (1) | L12: 2022, 2023, 2024, 2025
A13: RECTIFIC. HONEN PRAWEMA 6773934001 | B13: Gr. 65904 Rectificado GaPlus | C13: 242.15 | D13: 14529 | E13: 128 | F13: 64 | G13: 0.5 | H13: 113.50781 | I13: 1620 | J13: Otros (48); Calidad / medicion / proceso (20); Mecanica / desgaste / rotura (17) | K13: fuga neumatica (3); roturas de muela (2); rotura muela (2) | L13: 2022, 2023, 2024, 2025, 2026
A14: SOLDADORA PRO BEAM 6866224001 | B14: 66302 MQ-281 Engranajes Blanco | C14: 235.75 | D14: 14145 | E14: 221 | F14: 113 | G14: 0.51131222 | H14: 64.004525 | I14: 960 | J14: Otros (120); Mecanica / desgaste / rotura (29); Robot / carga / manipulacion (25) | K14: no funciona marcador láser (3); reparar nido (alabeo) (2); reparar nido (2) | L14: 2022, 2023, 2024, 2025, 2026
A15: RECTIFICADORA FELSOMAT 6773941003 | B15: Gr.65904 MQ-281 Corona Sincro | C15: 234.51667 | D15: 14071 | E15: 153 | F15: 80 | G15: 0.52287582 | H15: 91.96732 | I15: 3248 | J15: Otros (65); Robot / carga / manipulacion (47); Mecanica / desgaste / rotura (12) | K15: avería cargador (4); fallo virutero (3); fallo cargador (3) | L15: 2022, 2023, 2024, 2025, 2026
... A964: ISLA 10 CAMPANA ENERCON 6657770001 | B964: Gr. 31301 Inyección Cajas -Carcasas | C964: 0 | D964: 0 | E964: 2 | F964: 0 | G964: 0 | H964: 0 | I964: 0 | J964: Otros (1); Mecanica / desgaste / rotura (1) | K964: cierre armario campana isla 10 (1); maneta cierre campana rota (1) | L964: 2025
A965: (Sin maquina) | C965: 0 | D965: 0 | E965: 2 | F965: 0 | G965: 0 | H965: 0 | I965: 0 | J965: Otros (2)
A966: (Sin maquina) PC Scada Central Térmica no funciona | B966: Central Térmica | C966: 0 | D966: 0 | E966: 1 | F966: 0 | G966: 0 | H966: 0 | I966: 0 | J966: Electrico / PLC / PC / comunicacion (1) | K966: pc scada central térmica no funciona (1) | L966: 2023
A967: (Sin maquina) Cinta Ewab sin tapar | B967: Gr. 66511/04 Mecanizado Línea 4 | C967: 0 | D967: 0 | E967: 1 | F967: 0 | G967: 0 | H967: 0 | I967: 0 | J967: Calidad / medicion / proceso (1) | K967: cinta ewab sin tapar (1) | L967: 2023
A968: (Sin maquina) ACTUALIZAR FECHA DE ARTIS DE TODAS MAQUI | B968: Gr. 66511/06 Mecanizado Línea 5 | C968: 0 | D968: 0 | E968: 1 | F968: 0 | G968: 0 | H968: 0 | I968: 0 | J968: Calidad / medicion / proceso (1) | K968: actualizar fecha de artis de todas maqui (1) | L968: 2024
A969: (Sin maquina) motnar "T" en bomba desaceitadora | B969: Gr. 66511/06 Mecanizado Línea 5 | C969: 0 | D969: 0 | E969: 1 | F969: 0 | G969: 0 | H969: 0 | I969: 0 | J969: Refrigerante / agua / lavado (1) | K969: motnar "t" en bomba desaceitadora (1) | L969: 2026
A970: (Sin maquina) Cambiar ruedas a carro platos | B970: Grupo torneado | C970: 0 | D970: 0 | E970: 1 | F970: 0 | G970: 0 | H970: 0 | I970: 0 | J970: Otros (1) | K970: cambiar ruedas a carro platos (1) | L970: 2022
A971: (Sin maquina) CHASIS BICI PARTIDO | B971: Grupo torneado MQ-281 | C971: 0 | D971: 0 | E971: 1 | F971: 0 | G971: 0 | H971: 0 | I971: 0 | J971: Otros (1) | K971: chasis bici partido (1) | L971: 2026
A972: (Sin maquina) desconfiguración pather pañol | B972: INSTALACIONES | C972: 0 | D972: 0 | E972: 1 | F972: 0 | G972: 0 | H972: 0 | I972: 0 | J972: Otros (1) | K972: desconfiguración pather pañol (1) | L972: 2024
A973: (Sin maquina) Instalar GSD's y comprobar batería PG | B973: Secc. 486 Mantto.Instalaciones | C973: 0 | D973: 0 | E973: 1 | F973: 0 | G973: 0 | H973: 0 | I973: 0 | J973: Otros (1) | K973: instalar gsd's y comprobar batería pg (1) | L973: 2022
A974: (Sin maquina) ARMARIO SUMA | B974: Secc. 602 Torneado | C974: 0 | D974: 0 | E974: 1 | F974: 0 | G974: 0 | H974: 0 | I974: 0 | J974: Otros (1) | K974: armario suma (1) | L974: 2023
A975: ASPIRACIÓN HUMOS ABSOLENT 6872628001 | B975: Gr.65904 MQ-281 Engranajes Negro | C975: 0 | D975: 0 | E975: 1 | F975: 0 | G975: 0 | H975: 0 | I975: 0 | J975: Refrigerante / agua / lavado (1) | K975: filtro 3 alarma (1) | L975: 2025
A976: ASPIRACIÓN HUMOS ABSOLENT 6872629001 | B976: Gr.65904 MQ-281 Engranajes Negro | C976: 0 | D976: 0 | E976: 1 | F976: 0 | G976: 0 | H976: 0 | I976: 0 | J976: Refrigerante / agua / lavado (1) | K976: filtro 3 alarma (1) | L976: 2025
A977: ASPIRADOR AAF 6872635001 FELSOMAT 5ª | B977: Gr. 65904 Rectificado.Ka | C977: 0 | D977: 0 | E977: 1 | F977: 0 | G977: 0 | H977: 0 | I977: 0 | J977: Mecanica / desgaste / rotura (1) | K977: vibracion en sistema de aspirado (1) | L977: 2023
... A1106: CENTRO MECANIZ. GROB 90621(6780981024) | B1106: Máquinas inactivas temporalmente | C1106: 0 | D1106: 0 | E1106: 1 | F1106: 0 | G1106: 0 | H1106: 0 | I1106: 0 | J1106: Otros (1) | K1106: disco duro nok (1) | L1106: 2023
A1107: CENTRO MECANIZ. GROB 90542(6780981020) | B1107: Máquinas inactivas temporalmente | C1107: 0 | D1107: 0 | E1107: 1 | F1107: 0 | G1107: 0 | H1107: 0 | I1107: 0 | J1107: Otros (1) | L1107: 2023
A1108: ESTEREOSCOPIO LEICA MZ125 | B1108: Calidad Laboratorio T.T. | C1108: 0 | D1108: 0 | E1108: 1 | F1108: 0 | G1108: 0 | H1108: 0 | I1108: 0 | J1108: Calidad / medicion / proceso (1) | K1108: camara no funciona (1) | L1108: 2023
A1109: Carcasa 0DQ.301.107.C Molde nº7 | B1109: Secc. 298 Mantenimiento Moldes | C1109: 0 | D1109: 0 | E1109: 1 | F1109: 0 | G1109: 0 | H1109: 0 | I1109: 0 | J1109: Otros (1) | K1109: colocar puente en matriz (1) | L1109: 2023
A1110: Caja 02T.301.103 AE Molde nº47 | B1110: Secc. 298 Mantenimiento Moldes | C1110: 0 | D1110: 0 | E1110: 1 | F1110: 0 | G1110: 0 | H1110: 0 | I1110: 0 | J1110: Otros (1) | K1110: ordenadores sin luz (1) | L1110: 2023
A1111: PUESTO CONTROL J19-082 | B1111: Gr. 66418 Conjunto Buje-Maguitos | C1111: 0 | D1111: 0 | E1111: 1 | F1111: 0 | G1111: 0 | H1111: 0 | I1111: 0 | J1111: Electrico / PLC / PC / comunicacion (1) | K1111: sustituir 2 pantallas/luminarias (1) | L1111: 2023
A1112: ATEMPERADOR THERMOBIEHL 6766901002/4 | B1112: Gr. 31301 Inyección Cajas -Carcasas | C1112: 0 | D1112: 0 | E1112: 1 | F1112: 0 | G1112: 0 | H1112: 0 | I1112: 0 | J1112: Otros (1) | K1112: atemperador 27 av.llenado circuito 2 (1) | L1112: 2023
A1113: PUESTO CONTROL I26-269 | B1113: Gr. 66407 Bujes | C1113: 0 | D1113: 0 | E1113: 1 | F1113: 0 | G1113: 0 | H1113: 0 | I1113: 0 | J1113: Otros (1) | K1113: no va luminaria (1) | L1113: 2023
A1114: PUESTO CONTROL N28-337 | B1114: Grupo torneado | C1114: 0 | D1114: 0 | E1114: 1 | F1114: 0 | G1114: 0 | H1114: 0 | I1114: 0 | J1114: Calidad / medicion / proceso (1) | K1114: revisar y ajustar calibres (1) | L1114: 2023
A1115: (Sin maquina) Pinzas de almacen defectuosas linea 4 | B1115: Gr. 66511/04 Mecanizado Línea 4 | C1115: 0 | D1115: 0 | E1115: 1 | F1115: 0 | G1115: 0 | H1115: 0 | I1115: 0 | J1115: Calidad / medicion / proceso (1) | K1115: pinzas de almacen defectuosas linea 4 (1) | L1115: 2023
A1116: ESTUFA DIGITRONIC SELECTA | B1116: Calidad Laboratorio T.T. | C1116: 0 | D1116: 0 | E1116: 1 | F1116: 0 | G1116: 0 | H1116: 0 | I1116: 0 | J1116: Electrico / PLC / PC / comunicacion (1) | K1116: ventilador estufa funcionamiento nok (1) | L1116: 2023
...

Sheet ORG_M_06_Cuellos_Botella
A1: Cuellos de botella
A2: Todos los cuellos son A1 por definición. No se fuerza mapeo dudoso contra SAP.
A3: Modelo | B3: Línea | C3: Nombre CB | D3: OEE | E3: Criticidad
A4: 281-BLANCO | B4: 5ªVC-B-281 | C4: FELSOMAT 20004/5ª | D4: 0.93573743 | E4: A1 - Crítico por cuello de botella
A5: 281-BLANCO | B5: 5ªVP-B-281 | C5: FELSOMAT 20009 | D5: 0.93788845 | E5: A1 - Crítico por cuello de botella
A6: 281-NEGRO | B6: 6ªV.P-N-281 | C6: 16004 FELSOMAT | D6: 0.85009311 | E6: A1 - Crítico por cuello de botella
A7: SINCRO | B7: MANGUITO 3/6 | C7: 90343 | D7: 0.8915504 | E7: A1 - Crítico por cuello de botella
A8: SINCRO | B8: MANGUITO 1ª 2ª | C8: 90348 | D8: 0.89417701 | E8: A1 - Crítico por cuello de botella
A9: 281-NEGRO | B9: M.A-N-281 | C9: BUDERUS 41002 | D9: 0.88299187 | E9: A1 - Crítico por cuello de botella
A10: 281-NEGRO | B10: SEC-TW2-N-281 | C10: EMAG 42001 | D10: 0.86696438 | E10: A1 - Crítico por cuello de botella
A11: 281-NEGRO | B11: PRIM-N-281 | C11: EMAG 42002 | D11: 0.74241943 | E11: A1 - Crítico por cuello de botella
A12: 281-NEGRO | B12: SEC-TW1-N-281 | C12: EMAG 42003 | D12: 0.7404589 | E12: A1 - Crítico por cuello de botella
A13: T.T. | B13: H-15 | C13: EST-H15 | D13: 0.89959501 | E13: A1 - Crítico por cuello de botella
A14: 200-TORN | B14: 3ªVP-TORN-200-3ªP | C14: FAMAR 90381-3ªVP | D14: 0.82791393 | E14: A1 - Crítico por cuello de botella
A15: 200-TORN | B15: 4ªVP-TORN-200 | C15: FAMAR 90382 | D15: 0.82802865 | E15: A1 - Crítico por cuello de botella
... A132: 281-TORN | B132: 6ªVP-TORN-281 | C132: TAKISAWA 41003 | D132: 0.85171878 | E132: A1 - Crítico por cuello de botella

Sheet ORG_M_07_Contexto_Global
A1: Contexto global de planta
A2: Datos globales del alcance real. Sirven para dimensionamiento, aunque no haya inventario fila a fila.
A3: Bloque | B3: Cantidad | C3: Descripción | D3: Fuente
A4: Mecanizado | B4: 430 | C4: Máquinas de mecanizado | D4: Dato global de presentación
A5: Robots | B5: 92 | C5: Robots KUKA/FANUC/ABB/Universal | D5: Dato global de presentación
A6: Montaje | B6: 264 | C6: Filas de montaje en fichero actualizado. Incluye MQ-200, MQ-281 y MEB ECO con reservas/standby | D6: Fichero montaje actualizado
A7: Tratamientos y fundición | B7: 58 | C7: Instalaciones de tratamientos térmicos y fundición | D7: Dato global de presentación
A8: Calidad | B8: 290 | C8: Puestos de calidad, medición y control | D8: Dato global de presentación
A9: Lavadoras | B9: 74 | C9: Lavadoras automáticas | D9: Dato global de presentación
A10: Transporte instalaciones | B10: 355 | C10: Instalaciones de transporte | D10: Dato global de presentación
A11: Medios de transporte | B11: 386 | C11: Carros, apiladores, potros | D11: Dato global de presentación
A12: Auxiliares producción | B12: 94 | C12: Ingrávidos, atemperadores, aspiradores y auxiliares | D12: Dato global de presentación
A13: Preventivos | B13: 9000 | C13: Más de 9.000 planes PM | D13: Dato global de presentación
A14: Puntos PM | B14: 50000 | C14: Más de 50.000 puntos PM | D14: Dato global de presentación
A15: Avisos intervención | B15: 10000 | C15: Más de 10.000 avisos/año | D15: Dato global de presentación
... A17: Horas máquina parada | B17: 10000 | C17: 10.000 h de máquina parada declaradas | D17: Dato global de presentación

Sheet ORG_M_08_Dimensionamiento
A1: Dimensionamiento orientativo
A2: Separado entre carga base, PM/TPM y plantilla actual. Hablar de mantenedores equivalentes, no de contratación directa.
A3: Escenario | B3: Mantenedores equivalentes | C3: Lectura
A4: Plantilla actual | B4: 80 | C4: Dato facilitado por usuario
A5: Referencia base ajustada | B5: 100 | C5: Carga ponderada mínima defendible
A6: Referencia base equilibrada | B6: 114 | C6: Carga ponderada equilibrada
A7: Gap base mínimo | B7: 20 | C7: 100 - 80
A8: Gap base máximo | B8: 34 | C8: 114 - 80
A9: Referencia con PM/TPM no absorbidos - baja | B9: 110 | C9: Si PM/TPM no está absorbido
A10: Referencia con PM/TPM no absorbidos - alta | B10: 124 | C10: Si PM/TPM no está absorbido
A11: Gap con PM/TPM mínimo | B11: 30 | C11: 110 - 80
A12: Gap con PM/TPM máximo | B12: 44 | C12: 124 - 80
A15: Carga estructural | B15: Valor | C15: Lectura
A16: Planes PM | B16: > 9.000 | C16: Dato global
A17: Puntos PM | B17: > 50.000 | C17: Dato global
A18: Intervenciones TPM/año | B18: > 3.000 | C18: Dato global
A19: Avisos/año | B19: > 10.000 | C19: Dato global
A20: Horas productivas/FTE usadas en estimación | B20: 1450 | C20: Supuesto revisable

Sheet ORG_M_09_Reglas_Criterios
A1: Reglas, criterios y jerarquía
A2: Control para que el maestro no vuelva a desvirtuar los datos de negocio.
A3: Tipo | B3: Elemento | C3: Criterio
A4: Jerarquía | B4: MEB ECO | C4: Programa global de nuevos productos.
A5: Producto MEB ECO | B5: KMM | C5: 15 estaciones de montaje críticas.
A6: Producto MEB ECO | B6: EBOX | C6: 14 estaciones de montaje críticas.
A7: Producto MEB ECO | B7: Conjunto Diferencial | C7: 10 estaciones de montaje críticas + 4 rectificadoras Reishauer críticas.
A8: Producto MEB ECO | B8: Manguetas | C8: 17 estaciones de montaje críticas.
A9: Producto MEB ECO | B9: Aluminio GGH/MGH | C9: 15 máquinas críticas de mecanizado.
A10: Montaje convencional | B10: MQ-200 | C10: Fabricante KRAUSE.
A11: Montaje convencional | B11: MQ-281 | C11: Fabricante SCHMID.
A12: Criticidad | B12: Cuello de botella | C12: A1 siempre.
A13: Criticidad | B13: Inventario no identificado | C13: No se inventa. Se deja pendiente visible.
A14: Dimensionamiento | B14: Mantenedores equivalentes | C14: Se compara carga vs plantilla, no contratación directa.

Sheet ORG_D_00_Resumen
A1: Resumen ejecutivo
A2: Dimensionamiento mantenimiento PK-16 | Parque completo + carga real + fuentes externas
A4: KPIs principales
A5: Métrica | B5: Valor | C5: Unidad | D5: Lectura | E5: Fuente / cálculo | F5: Tipo | G5: Validación | H5: Comentario
A6: Parque global visible | B6: 2043 | C6: activos | D6: Todo el parque visible considerado | E6: MAESTRO_FABRICA_FINAL.xlsx | F6: Importado | G6: OK | H6: Incluye mecanizado, robots, montaje, calidad, transporte, lavadoras y auxiliares
A7: Activos clasificados | B7: 1646 | C7: activos | D7: Con criticidad A/B/C/D en maestro | E7: MAESTRO_FABRICA_FINAL.xlsx | F7: Importado | G7: OK
A8: No clasificados incluidos | B8: 397 | C8: activos | D8: Tratados como D/ruta para no perder carga | E8: Cálculo: parque visible - clasificados | F8: Derivado | G8: OK | H8: Criterio conservador de cobertura mínima
A9: Horas avería 2025→actual | B9: 29627.2 | C9: h | D9: Dato de soporte, no único driver | E9: MAESTRO_CRITICIDAD_MAQUINAS.xlsx | F9: Importado | G9: OK | H9: Campo Años contiene 2025/2026
A10: Base ratio parque completo | B10: 68.1 | C10: FTE | D10: FTE por criticidad completa | E10: SUMA A/12 + B/20 + C/35 + D/60 | F10: Fórmula | G10: OK
A11: PM + avisos | B11: 9.5 | C11: FTE | D11: Carga central anual adicional | E11: 60.000 / 6.300 unidades FTE/año | F11: Fórmula | G11: OK | H11: TPM excluido
A12: Formación anual | B12: 3 | C12: FTE | D12: Pérdida de capacidad por formación | E12: 80 pers. × 55 h / 1.450 h | F12: Fórmula | G12: OK
A13: Sábados + libranza | B13: 2 | C13: FTE | D13: Cobertura sábado y descanso semanal | E13: 10 pers/sábado × 45 / 220 | F13: Fórmula | G13: OK
A14: Cobertura real mínima | B14: 11.6 | C14: FTE | D14: Especialidades, turnos, ausencias | E14: 15% sobre base + PM/avisos | F14: Fórmula | G14: OK
A15: Cobertura real máxima | B15: 19.4 | C15: FTE | D15: Especialidades, turnos, ausencias | E15: 25% sobre base + PM/avisos | F15: Fórmula | G15: OK
A16: Necesidad final mínima | B16: 94.4 | C16: FTE | D16: Escenario defendible bajo | E16: Base + PM + formación + sábados + cobertura mín. | F16: Fórmula | G16: OK
A17: Necesidad final máxima | B17: 102.2 | C17: FTE | D17: Escenario defendible alto | E17: Base + PM + formación + sábados + cobertura máx. | F17: Fórmula | G17: OK
A18: Gap mínimo vs 80 nominales | B18: 14.4 | C18: FTE | D18: Déficit mínimo estimado | E18: Necesidad mínima - 80 | F18: Fórmula | G18: OK
A19: Gap máximo vs 80 nominales | B19: 22.2 | C19: FTE | D19: Déficit máximo estimado | E19: Necesidad máxima - 80 | F19: Fórmula | G19: OK
A22: Conclusión para dirección
A23: Necesidad estimada: 94-102 FTE. Frente a 80 personas nominales, el gap defendible queda en +14 a +22 FTE. El cálculo usa parque completo, activos no clasificados como D/ruta, PM+avisos, formación, sábados/libranza y cobertura real.

Sheet ORG_D_01_Supuestos_Fuentes
A1: Supuestos, fuentes y trazabilidad
A2: Dimensionamiento mantenimiento PK-16 | Parque completo + carga real + fuentes externas
A4: Supuestos editables
A5: Variable | B5: Valor | C5: Unidad | D5: Descripción | E5: Fuente | F5: Tipo
A6: Plantilla nominal actual | B6: 80 | C6: personas | D6: Plantilla de referencia comunicada por usuario | E6: Usuario / conversación | F6: Input
A7: Formación anual por persona | B7: 55 | C7: h/persona/año | D7: Horas de formación anual por mantenedor | E7: Supuesto usuario / modelo | F7: Input
A8: Horas productivas por FTE | B8: 1450 | C8: h/FTE/año | D8: Horas productivas anuales usadas para convertir horas a FTE | E8: Supuesto modelo | F8: Input
A9: Personas por sábado | B9: 10 | C9: personas/sábado | D9: Cobertura media requerida por sábado | E9: Supuesto usuario / modelo | F9: Input
A10: Sábados trabajados/año | B10: 45 | C10: sábados/año | D10: Sábados anuales con cobertura | E10: Supuesto modelo | F10: Input
A11: Días laborables/año | B11: 220 | C11: días/año | D11: Base para convertir libranza de sábados a FTE | E11: Supuesto modelo | F11: Input
A12: PM + avisos central | B12: 60000 | C12: unidades/año | D12: 50.000 PM + 10.000 avisos | E12: MAESTRO_FABRICA_FINAL.xlsx | F12: Importado
A13: Productividad PM/avisos por FTE | B13: 6300 | C13: unidades/FTE/año | D13: Hipótesis de conversión PM+avisos a FTE | E13: Supuesto modelo | F13: Input
A14: Cobertura real mínima | B14: 0.15 | C14: % | D14: Factor por turnos, especialidades, vacaciones, ausencias, simultaneidad | E14: Supuesto modelo | F14: Input
A15: Cobertura real máxima | B15: 0.25 | C15: % | D15: Factor por turnos, especialidades, vacaciones, ausencias, simultaneidad | E15: Supuesto modelo | F15: Input
A18: Fuentes externas para defender metodología
A19: Fuente | B19: Uso en defensa | C19: URL | D19: Mensaje para dirección | E19: Aplicación al modelo | F19: Nota
A20: SMRP Best Practices Metrics & Guidelines | B20: Métricas y benchmarking de mantenimiento y fiabilidad | C20: https://smrp.org/Learning-Resources/SMRP-Library/Best-Practices-Metrics-Guidelines/ | D20: SMRP estandariza métricas y benchmarks para programas de mantenimiento y fiabilidad. | E20: Se cita como fuente externa de benchmarking y métrica, no como ratio universal máquinas/mantenedor. | F20: Usar literalmente como “referencia externa de benchmark”.
A21: NASA NPR 8831.2F Facilities Maintenance and Operations Management | B21: Dimensionamiento por carga de trabajo, work requirements, work orders y staffing | C21: https://nodis3.gsfc.nasa.gov/displayDir.cfm?t=NPR&c=8831&s=2F | D21: NASA estructura mantenimiento por recursos, staffing, plan anual, requisitos de trabajo y ejecución. | E21: Se cita como fuente externa oficial para justificar cálculo por workload, PM/correctivo y recursos. | F21: Usar literalmente como “metodología de workload/staffing”.
A22: MAESTRO_FABRICA_FINAL.xlsx | B22: Datos internos de parque, PM, avisos, MEB ECO | C22: Archivo interno | D22: Parque completo y carga anual de mantenimiento. | E22: Base de datos principal para conteo de activos y carga central. | F22: Fuente interna.
A23: MAESTRO_CRITICIDAD_MAQUINAS.xlsx | B23: Criticidad, ratios internos, averías 2025→actual | C23: Archivo interno | D23: Criterio interno A/B/C/D aplicado a la cartera. | E23: Base de ratio interno y evidencia de averías/paros. | F23: Fuente interna.

Sheet ORG_D_02_Parque_Criticidad
A1: Parque completo y criticidad
A2: Dimensionamiento mantenimiento PK-16 | Parque completo + carga real + fuentes externas
A4: Contexto por familias de activo
A5: Familia de activo | B5: Cantidad | C5: Fuente | D5: Comentario
A6: Mecanizado | B6: 430 | C6: MAESTRO_FABRICA_FINAL.xlsx | D6: Incluido en parque global visible
A7: Robots | B7: 92 | C7: MAESTRO_FABRICA_FINAL.xlsx | D7: Incluido en parque global visible
A8: Montaje | B8: 264 | C8: MAESTRO_FABRICA_FINAL.xlsx | D8: Incluido en parque global visible
A9: Tratamientos/fundición | B9: 58 | C9: MAESTRO_FABRICA_FINAL.xlsx | D9: Incluido en parque global visible
A10: Calidad/control | B10: 290 | C10: MAESTRO_FABRICA_FINAL.xlsx | D10: Incluido en parque global visible
A11: Lavadoras | B11: 74 | C11: MAESTRO_FABRICA_FINAL.xlsx | D11: Incluido en parque global visible
A12: Inst. transporte | B12: 355 | C12: MAESTRO_FABRICA_FINAL.xlsx | D12: Incluido en parque global visible
A13: Medios transporte | B13: 386 | C13: MAESTRO_FABRICA_FINAL.xlsx | D13: Incluido en parque global visible
A14: Auxiliares prod. | B14: 94 | C14: MAESTRO_FABRICA_FINAL.xlsx | D14: Incluido en parque global visible
A15: TOTAL PARQUE VISIBLE | B15: 2043 | C15: Fórmula | D15: Debe cuadrar con 2.043
A17: Criticidad completa usada para cálculo
A18: Criticidad | B18: Activos | C18: Ratio aplicado | D18: FTE base | E18: Comentario
A19: A | B19: 418 | C19: 12 | D19: 34.833333 | E19: Críticos / cuello / alta criticidad
A20: B | B20: 275 | C20: 20 | D20: 13.75 | E20: Críticos medios
A21: C | B21: 1200 | C21: 35 | D21: 34.285714 | E21: Carga media
A22: D | B22: 150 | C22: 60 | D22: 2.5 | E22: Baja criticidad + no clasificados como D/ruta
A23: TOTAL | B23: 2043 | D23: 85.369048

Sheet ORG_D_03_Secciones
A1: Secciones / productos
A2: Dimensionamiento mantenimiento PK-16 | Parque completo + carga real + fuentes externas
A4: FTE base por sección / producto
A5: Sección / producto | B5: A | C5: B | D5: C | E5: D | F5: A_MEB | G5: FTE base | H5: Comentario
A6: MQ200 | B6: 117 | C6: 19 | D6: 6 | E6: 29 | F6: 0 | G6: 11.354762 | H6: Incluye parque histórico identificado y/o MEB ECO si aplica
A7: MQ281 | B7: 65 | C7: 36 | D7: 38 | E7: 57 | F7: 0 | G7: 9.252381 | H7: Incluye parque histórico identificado y/o MEB ECO si aplica
A8: EBOX | B8: 14 | C8: 0 | D8: 0 | E8: 0 | F8: 14 | G8: 2.3333333 | H8: Incluye parque histórico identificado y/o MEB ECO si aplica
A9: MANGUETAS | B9: 17 | C9: 0 | D9: 0 | E9: 0 | F9: 17 | G9: 2.8333333 | H9: Incluye parque histórico identificado y/o MEB ECO si aplica
A10: KMM | B10: 15 | C10: 0 | D10: 0 | E10: 0 | F10: 15 | G10: 2.5 | H10: Incluye parque histórico identificado y/o MEB ECO si aplica
A11: CONJ. DIF. | B11: 14 | C11: 0 | D11: 5 | E11: 17 | F11: 14 | G11: 2.7595238 | H11: Incluye parque histórico identificado y/o MEB ECO si aplica
A12: ALUMINIO GGH/MGH | B12: 15 | C12: 3 | D12: 0 | E12: 0 | F12: 15 | G12: 2.65 | H12: Incluye parque histórico identificado y/o MEB ECO si aplica
A13: RESTO PLANTA / SOPORTE GLOBAL | G13: 51.685714 | H13: Resto de activos de fábrica para cuadrar contra parque completo
A14: TOTAL BASE PARQUE COMPLETO | G14: 85.369048 | H14: Debe cuadrar con base por criticidad completa

Sheet ORG_D_04_Calculo_FTE
A1: Cálculo FTE final
A2: Dimensionamiento mantenimiento PK-16 | Parque completo + carga real + fuentes externas
A4: Cálculo final con fórmulas
A5: Concepto | B5: Fórmula / valor | C5: Unidad | D5: Fuente | E5: Comentario | F5: Tipo | H5: Concepto | I5: FTE
A6: Base ratio parque completo | B6: 85.369048 | C6: FTE | D6: 03_Secciones | E6: A/12 + B/20 + C/35 + D/60 + no clasificados como D/ruta | F6: Fórmula | H6: Necesidad mín. | I6: 114.20672
